Workbook

Sheet Retes X grupo
A1: GRUPO | B1: % RETE CTA | C1: Beneficio
A2: GRUPO FERNANDEZ | B2: 0.75216138 | C2: 0.4137931
A3: GRUPO PLAZA | B3: 0.65333333 | C3: 0.37755102
A4: Total general | B4: 0.722334 | C4: 0.40389972

Sheet Retes X asesor
A1: Asesor | B1: % RETE CTA | C1: Beneficio
A2: AGUILA, PATRICIA MILAGROS DANIELA | B2: 0.5 | C2: 0.5
A3: AGUIRRE, ERIKA ALEJANDRA | B3: 0.81818182 | C3: 0.59259259
A4: ALARCON, LEISA SAMIRA | B4: 0.81818182 | C4: 0.61111111
A5: ALEGRE, CAROLINA ESTEFANIA | B5: 0.7 | C5: 0.57142857
A6: ALENDREZ, SABRINA BEATRIZ | B6: 0.77777778 | C6: 0.42857143
A7: ALVIRA, CRISTIAN EMANUEL | B7: 0.64285714 | C7: 0.27777778
A8: ARANDA, ROMINA MAITEN | B8: 0.8 | C8: 0.5
A9: CACERES, IGNACIO ALEJO | B9: 0.8 | C9: 0.33333333
A10: DELISANO, MAGALI CINTHIA | B10: 0.84615385 | C10: 0.18181818
A11: DUERO, CAMILA AYLEN | B11: 0.33333333 | C11: 0.5
A12: ENSISO, PEDRO SEBASTIAN | B12: 0.82608696 | C12: 0.36842105
A13: FUENTES, PAULA ELIZABETH | B13: 0.16666667 | C13: 0
... A30: Total general | B30: 0.722334 | C30: 0.40389972

Sheet Resumen Retes
A1: Asesor | B1: Retes Positivas | C1: Retes Negativas | D1: Total Retenciones
A2: AGUILA, PATRICIA MILAGROS DANIELA | B2: 2 | C2: 2 | D2: 4
A3: AGUIRRE, ERIKA ALEJANDRA | B3: 27 | C3: 6 | D3: 33
A4: ALARCON, LEISA SAMIRA | B4: 18 | C4: 4 | D4: 22
A5: ALEGRE, CAROLINA ESTEFANIA | B5: 7 | C5: 3 | D5: 10
A6: ALENDREZ, SABRINA BEATRIZ | B6: 7 | C6: 2 | D6: 9
A7: ALVIRA, CRISTIAN EMANUEL | B7: 18 | C7: 10 | D7: 28
A8: ARANDA, ROMINA MAITEN | B8: 8 | C8: 2 | D8: 10
A9: CACERES, IGNACIO ALEJO | B9: 12 | C9: 3 | D9: 15
A10: DELISANO, MAGALI CINTHIA | B10: 11 | C10: 2 | D10: 13
A11: DUERO, CAMILA AYLEN | B11: 2 | C11: 4 | D11: 6
A12: ENSISO, PEDRO SEBASTIAN | B12: 19 | C12: 4 | D12: 23
A13: FUENTES, PAULA ELIZABETH | B13: 1 | C13: 5 | D13: 6
... A30: Total general | B30: 359 | C30: 138 | D30: 497

Sheet Hoja1
A3: Cuenta de Acción Retención | B3: Etiquetas de columna
A4: Etiquetas de fila | B4: Baja | C4: Baja Con Ret Amex + Ca $ | D4: Baja Con Ret Ca $ | E4: Baja Con Ret Visa | F4: Baja Con Ret Visa + Amex | G4: Baja Con Ret Visa + Amex + Ca $ | H4: Baja Con Ret Visa + Ca $ | I4: Mant Beneficio | J4: Ret Beneficio | K4: Ret Beneficio 3 meses al 100% | L4: Ret Cta Sueldo | M4: Ret X Bonificacion Mantenimiento | N4: Ret X Bonificacion Mantenimiento 12 meses al 100% | O4: Ret X Bonificacion Mantenimiento 12 meses al 50% | P4: Ret X Bonificacion Mantenimiento 3 meses al 100% | Q4: Total general
A5: AGUIRRE, ERIKA ALEJANDRA | B5: 12 | E5: 1 | G5: 1 | H5: 1 | I5: 21 | L5: 9 | N5: 8 | O5: 15 | P5: 10 | Q5: 78
A6: ALARCON, LEISA SAMIRA | B6: 6 | H6: 1 | I6: 11 | J6: 1 | L6: 8 | N6: 2 | O6: 10 | P6: 4 | Q6: 43
A7: ALEGRE, CAROLINA ESTEFANIA | B7: 6 | F7: 2 | I7: 5 | L7: 2 | O7: 5 | P7: 2 | Q7: 22
A8: ALENDREZ, SABRINA BEATRIZ | B8: 1 | I8: 2 | L8: 3 | N8: 3 | O8: 2 | Q8: 11
A9: ALVIRA, CRISTIAN EMANUEL | B9: 12 | D9: 1 | H9: 3 | I9: 8 | L9: 8 | N9: 7 | O9: 1 | P9: 5 | Q9: 45
A10: ARANDA, ROMINA MAITEN | B10: 5 | D10: 2 | G10: 2 | I10: 13 | L10: 7 | N10: 10 | O10: 5 | P10: 2 | Q10: 46
A11: CACERES, IGNACIO ALEJO | B11: 12 | C11: 1 | D11: 1 | G11: 2 | I11: 4 | L11: 5 | N11: 1 | O11: 3 | P11: 5 | Q11: 34
A12: CACERES, NOELIA NAHIR | B12: 9 | E12: 1 | I12: 8 | L12: 8 | N12: 5 | O12: 3 | P12: 2 | Q12: 36
A13: DELISANO, MAGALI CINTHIA | B13: 2 | D13: 1 | I13: 9 | J13: 3 | L13: 1 | N13: 11 | O13: 2 | P13: 2 | Q13: 31
A14: DUERO, CAMILA AYLEN | B14: 4 | I14: 2 | O14: 1 | P14: 3 | Q14: 10
A15: ENSISO, PEDRO SEBASTIAN | B15: 4 | D15: 3 | I15: 7 | J15: 1 | N15: 8 | O15: 6 | Q15: 29
A16: GAVILAN, JOHANA EUGENIA | B16: 5 | I16: 1 | L16: 5 | N16: 2 | O16: 5 | P16: 5 | Q16: 23
A17: GONZALEZ, DANIELA SOLEDAD | B17: 2 | I17: 6 | L17: 4 | N17: 1 | O17: 6 | P17: 3 | Q17: 22
A18: HERRERA, SOFIA AILEN | B18: 7 | D18: 2 | H18: 1 | I18: 7 | L18: 6 | N18: 7 | O18: 2 | P18: 2 | Q18: 34
A19: LEIVA, MARIA DE LOS ANGELES | B19: 11 | F19: 1 | G19: 2 | H19: 1 | I19: 8 | L19: 1 | N19: 2 | O19: 1 | P19: 3 | Q19: 30
A20: LUDUENA, VALENTINA CARLA | B20: 9 | D20: 1 | F20: 1 | G20: 1 | I20: 7 | J20: 1 | L20: 8 | N20: 5 | O20: 15 | P20: 12 | Q20: 60
A21: MARTINEZ, LILIAN ADELA | B21: 13 | D21: 1 | E21: 1 | G21: 2 | H21: 3 | I21: 12 | J21: 9 | K21: 1 | L21: 1 | N21: 14 | O21: 8 | Q21: 65
A22: MARTINEZ, MIRIAM | B22: 15 | D22: 3 | H22: 1 | I22: 7 | L22: 5 | N22: 3 | O22: 2 | P22: 1 | Q22: 37
A23: MIRANDA, DIEGO VALENTIN ALEJANDRO | B23: 7 | E23: 2 | H23: 1 | I23: 4 | L23: 2 | N23: 1 | O23: 5 | P23: 3 | Q23: 25
A24: MONTOYA BUSTAMANTE, CELIA ERNESTINA | I24: 13 | L24: 14 | N24: 8 | O24: 1 | P24: 1 | Q24: 37
A25: NUNEZ, LUDMILA BELEN | B25: 1 | D25: 1 | I25: 6 | L25: 2 | N25: 2 | O25: 6 | P25: 1 | Q25: 19
A26: OTEIZA, LUCAS MAXIMILIANO | B26: 29 | D26: 3 | E26: 1 | F26: 1 | G26: 1 | H26: 3 | I26: 13 | L26: 2 | N26: 13 | O26: 12 | P26: 7 | Q26: 85
A27: ROLDAN, ADRIEL RODOLFO | B27: 15 | D27: 1 | G27: 2 | I27: 18 | J27: 9 | N27: 9 | O27: 9 | P27: 7 | Q27: 70
A28: ROMAN FERNANDEZ, LETICIA | B28: 11 | D28: 1 | F28: 1 | G28: 1 | H28: 1 | I28: 3 | L28: 1 | M28: 1 | N28: 11 | O28: 3 | P28: 4 | Q28: 38
A29: SUAREZ, YAMILA BELEN | B29: 13 | D29: 1 | F29: 1 | G29: 1 | I29: 17 | L29: 9 | N29: 12 | O29: 10 | P29: 1 | Q29: 65
A30: Total general | B30: 211 | C30: 1 | D30: 22 | E30: 6 | F30: 7 | G30: 15 | H30: 16 | I30: 212 | J30: 24 | K30: 1 | L30: 111 | M30: 1 | N30: 145 | O30: 138 | P30: 85 | Q30: 995
A32: Etiquetas de fila | B32: Retes Positivas | C32: Retes Negativas | D32: Total Retenciones
A33: AGUIRRE, ERIKA ALEJANDRA | B33: =SUM(Hoja1!I5:P5) -> 63 | C33: =SUM(B5:H5) -> 15 | D33: =SUM(B33:C33) -> 78
A34: ALARCON, LEISA SAMIRA | B34: =SUM(Hoja1!I6:P6) -> 36 | C34: =SUM(B6:H6) -> 7 | D34: =SUM(B34:C34) -> 43
A35: ALEGRE, CAROLINA ESTEFANIA | B35: =SUM(Hoja1!I7:P7) -> 14 | C35: =SUM(B7:H7) -> 8 | D35: =SUM(B35:C35) -> 22
A36: ALENDREZ, SABRINA BEATRIZ | B36: =SUM(Hoja1!I8:P8) -> 10 | C36: =SUM(B8:H8) -> 1 | D36: =SUM(B36:C36) -> 11
A37: ALVIRA, CRISTIAN EMANUEL | B37: =SUM(Hoja1!I9:P9) -> 29 | C37: =SUM(B9:H9) -> 16 | D37: =SUM(B37:C37) -> 45
A38: ARANDA, ROMINA MAITEN | B38: =SUM(Hoja1!I10:P10) -> 37 | C38: =SUM(B10:H10) -> 9 | D38: =SUM(B38:C38) -> 46
A39: CACERES, IGNACIO ALEJO | B39: =SUM(Hoja1!I11:P11) -> 18 | C39: =SUM(B11:H11) -> 16 | D39: =SUM(B39:C39) -> 34
A40: CACERES, NOELIA NAHIR | B40: =SUM(Hoja1!I12:P12) -> 26 | C40: =SUM(B12:H12) -> 10 | D40: =SUM(B40:C40) -> 36
A41: DELISANO, MAGALI CINTHIA | B41: =SUM(Hoja1!I13:P13) -> 28 | C41: =SUM(B13:H13) -> 3 | D41: =SUM(B41:C41) -> 31
A42: DUERO, CAMILA AYLEN | B42: =SUM(Hoja1!I14:P14) -> 6 | C42: =SUM(B14:H14) -> 4 | D42: =SUM(B42:C42) -> 10
A43: ENSISO, PEDRO SEBASTIAN | B43: =SUM(Hoja1!I15:P15) -> 22 | C43: =SUM(B15:H15) -> 7 | D43: =SUM(B43:C43) -> 29
...

Sheet Sheet1
A1: Filtros aplicados: Periodo Encuesta es 202606 D_EMPRESA es LA JUANITA
A3: Periodo PV | B3: Negocio | C3: Empresa | D3: Jefe | E3: Grupo | F3: Supervisor | G3: Ejecutivo Legajo | H3: Ejecutivo | I3: Fecha Encuesta | J3: Nup | K3: Producto | L3: Motivo Baja | M3: Acción Retención | N3: Resultado PV | O3: Resultado Original
A4: 202607 | B4: NEGOCIO CORDOBA | C4: LA JUANITA | D4: CORDOBA,MARIANA ELIZABETH | E4: GRUPO FERNANDEZ | F4: DE ESTEBAN, MARIA FLORENCIA | G4: B048943 | H4: MARTINEZ, LILIAN ADELA | I4: 46203 | J4: 11083676 | K4: Cuenta Infinity Platinum | L4: Costo de mantenimiento | M4: Baja | N4: NEGATIVA | O4: NEGATIVA
A5: 202607 | B5: NEGOCIO CORDOBA | C5: LA JUANITA | D5: CORDOBA,MARIANA ELIZABETH | E5: GRUPO FERNANDEZ | F5: DE ESTEBAN, MARIA FLORENCIA | G5: B048943 | H5: MARTINEZ, LILIAN ADELA | I5: 46203 | J5: 30777516 | K5: Cuenta Super Cuenta 3 | L5: Costo de mantenimiento | M5: Ret X Bonificacion Mantenimiento 12 meses al 100% | N5: POSITIVA | O5: POSITIVA
A6: 202607 | B6: NEGOCIO CORDOBA | C6: LA JUANITA | D6: CORDOBA,MARIANA ELIZABETH | E6: GRUPO FERNANDEZ | F6: DE ESTEBAN, MARIA FLORENCIA | G6: B048943 | H6: MARTINEZ, LILIAN ADELA | I6: 46203 | J6: 50618856 | K6: Cuenta Infinity Gold | L6: Costo de mantenimiento | M6: Ret X Bonificacion Mantenimiento 12 meses al 100% | N6: POSITIVA | O6: POSITIVA
A7: 202607 | B7: NEGOCIO CORDOBA | C7: LA JUANITA | D7: CORDOBA,MARIANA ELIZABETH | E7: GRUPO FERNANDEZ | F7: DE ESTEBAN, MARIA FLORENCIA | G7: B048943 | H7: MARTINEZ, LILIAN ADELA | I7: 46203 | J7: 90582878 | K7: Cuenta Infinity Gold | L7: Costo de mantenimiento | M7: Baja Con Ret Visa | N7: NEGATIVA | O7: NEGATIVA
A8: 202607 | B8: NEGOCIO CORDOBA | C8: LA JUANITA | D8: CORDOBA,MARIANA ELIZABETH | E8: GRUPO FERNANDEZ | F8: DE ESTEBAN, MARIA FLORENCIA | G8: B050112 | H8: MONTOYA BUSTAMANTE, CELIA ERNESTINA | I8: 46203 | J8: 20787732 | K8: Cuenta Infinity Gold | L8: Costo de mantenimiento | M8: Ret X Bonificacion Mantenimiento 12 meses al 100% | N8: POSITIVA | O8: POSITIVA
A9: 202607 | B9: NEGOCIO CORDOBA | C9: LA JUANITA | D9: CORDOBA,MARIANA ELIZABETH | E9: GRUPO FERNANDEZ | F9: DE ESTEBAN, MARIA FLORENCIA | G9: B050112 | H9: MONTOYA BUSTAMANTE, CELIA ERNESTINA | I9: 46203 | J9: 20799561 | K9: Cuenta Super Cuenta 3 | L9: Cambio de trabajo o decisión de la empresa donde trabajo | M9: Ret Cta Sueldo | N9: POSITIVA | O9: POSITIVA
A10: 202607 | B10: NEGOCIO CORDOBA | C10: LA JUANITA | D10: CORDOBA,MARIANA ELIZABETH | E10: GRUPO FERNANDEZ | F10: DE ESTEBAN, MARIA FLORENCIA | G10: B050112 | H10: MONTOYA BUSTAMANTE, CELIA ERNESTINA | I10: 46203 | J10: 80753601 | K10: Cuenta Infinity Platinum | L10: Cambio de trabajo o decisión de la empresa donde trabajo | M10: Ret Cta Sueldo | N10: POSITIVA | O10: POSITIVA
A11: 202607 | B11: NEGOCIO CORDOBA | C11: LA JUANITA | D11: CORDOBA,MARIANA ELIZABETH | E11: GRUPO FERNANDEZ | F11: DE ESTEBAN, MARIA FLORENCIA | G11: B053093 | H11: CACERES, IGNACIO ALEJO | I11: 46203 | J11: 1048722 | K11: Cuenta Infinity Platinum | L11: Costo de mantenimiento | M11: Baja | N11: NEGATIVA | O11: NEGATIVA
A12: 202607 | B12: NEGOCIO CORDOBA | C12: LA JUANITA | D12: CORDOBA,MARIANA ELIZABETH | E12: GRUPO FERNANDEZ | F12: DE ESTEBAN, MARIA FLORENCIA | G12: B053093 | H12: CACERES, IGNACIO ALEJO | I12: 46203 | J12: 92201087 | K12: Cuenta Infinity Platinum | L12: Costo de mantenimiento | M12: Ret Cta Sueldo | N12: POSITIVA | O12: POSITIVA
A13: 202607 | B13: NEGOCIO CORDOBA | C13: LA JUANITA | D13: CORDOBA,MARIANA ELIZABETH | E13: GRUPO FERNANDEZ | F13: DE ESTEBAN, MARIA FLORENCIA | G13: B053453 | H13: AGUIRRE, ERIKA ALEJANDRA | I13: 46203 | J13: 20508209 | K13: Cuenta Infinity Black | L13: Costo de mantenimiento | M13: Ret X Bonificacion Mantenimiento 12 meses al 50% | N13: POSITIVA | O13: POSITIVA
A14: 202607 | B14: NEGOCIO CORDOBA | C14: LA JUANITA | D14: CORDOBA,MARIANA ELIZABETH | E14: GRUPO FERNANDEZ | F14: DE ESTEBAN, MARIA FLORENCIA | G14: B053453 | H14: AGUIRRE, ERIKA ALEJANDRA | I14: 46203 | J14: 3926830 | K14: Cuenta Infinity Black | L14: Costo de mantenimiento | M14: Mant Beneficio | N14: POSITIVA | O14: POSITIVA
A15: 202607 | B15: NEGOCIO CORDOBA | C15: LA JUANITA | D15: CORDOBA,MARIANA ELIZABETH | E15: GRUPO FERNANDEZ | F15: DE ESTEBAN, MARIA FLORENCIA | G15: B053453 | H15: AGUIRRE, ERIKA ALEJANDRA | I15: 46203 | J15: 5812568 | K15: Cuenta Infinity Platinum | L15: Costo de mantenimiento | M15: Ret X Bonificacion Mantenimiento 3 meses al 100% | N15: POSITIVA | O15: POSITIVA
... A998: 202607 | B998: NEGOCIO CORDOBA | C998: LA JUANITA | D998: CORDOBA,MARIANA ELIZABETH | E998: GRUPO PLAZA | F998: HUESPE, EDUARDO ALEJANDRO | G998: B074137 | H998: LEIVA, MARIA DE LOS ANGELES | I998: 46174 | J998: 30751623 | K998: Cuenta Infinity Gold | L998: Costo de mantenimiento | M998: Baja | N998: NEGATIVA | O998: NEGATIVA
